2025-09-12 11:39:07,763 - TeleBot - ERROR - Infinity polling: polling exited
2025-09-12 11:39:07,763 - TeleBot - ERROR - Break infinity polling
2025-09-12 11:42:42,952 - TeleBot - ERROR - Infinity polling: polling exited
2025-09-12 11:42:42,952 - TeleBot - ERROR - Break infinity polling
2025-09-20 10:35:39,453 - TeleBot - ERROR - Infinity polling: polling exited
2025-09-20 10:35:39,454 - TeleBot - ERROR - Break infinity polling
2025-09-20 10:39:51,063 - TeleBot - ERROR - Infinity polling: polling exited
2025-09-20 10:39:51,064 - TeleBot - ERROR - Break infinity polling
2025-09-20 10:40:29,046 - TeleBot - ERROR - Infinity polling exception: 'TeleBot' object has no attribute 'send_messagem'
2025-09-20 10:40:29,065 - TeleBot - ERROR - Exception traceback:
Traceback (most recent call last):
  File "D:\Projects\TgBot\pythonProject1\.venv\Lib\site-packages\telebot\__init__.py", line 1110, in infinity_polling
    self.polling(non_stop=True, timeout=timeout, long_polling_timeout=long_polling_timeout,
  File "D:\Projects\TgBot\pythonProject1\.venv\Lib\site-packages\telebot\__init__.py", line 1198, in polling
    self.__threaded_polling(non_stop=non_stop, interval=interval, timeout=timeout, long_polling_timeout=long_polling_timeout,
  File "D:\Projects\TgBot\pythonProject1\.venv\Lib\site-packages\telebot\__init__.py", line 1273, in __threaded_polling
    raise e
  File "D:\Projects\TgBot\pythonProject1\.venv\Lib\site-packages\telebot\__init__.py", line 1235, in __threaded_polling
    self.worker_pool.raise_exceptions()
  File "D:\Projects\TgBot\pythonProject1\.venv\Lib\site-packages\telebot\util.py", line 154, in raise_exceptions
    raise self.exception_info
  File "D:\Projects\TgBot\pythonProject1\.venv\Lib\site-packages\telebot\util.py", line 97, in run
    task(*args, **kwargs)
  File "D:\Projects\TgBot\pythonProject1\.venv\Lib\site-packages\telebot\__init__.py", line 10134, in _run_middlewares_and_handler
    result = handler['function'](message)
             ^^^^^^^^^^^^^^^^^^^^^^^^^^^^
  File "D:\Projects\TgBot\pythonProject1\main.py", line 75, in hide_kb
    rm =types.ReplyKeyboardRemove()
    ^^^^^^^^^^^^^^^^^
AttributeError: 'TeleBot' object has no attribute 'send_messagem'. Did you mean: 'send_message'?

2025-09-20 10:40:50,108 - TeleBot - ERROR - Infinity polling: polling exited
2025-09-20 10:40:50,108 - TeleBot - ERROR - Break infinity polling
2025-09-20 10:43:05,121 - TeleBot - ERROR - Infinity polling: polling exited
2025-09-20 10:43:05,121 - TeleBot - ERROR - Break infinity polling
2025-09-20 10:46:03,223 - TeleBot - ERROR - Infinity polling: polling exited
2025-09-20 10:46:03,223 - TeleBot - ERROR - Break infinity polling
2025-09-20 11:02:14,989 - TeleBot - ERROR - Infinity polling: polling exited
2025-09-20 11:02:14,989 - TeleBot - ERROR - Break infinity polling
2025-09-20 11:21:44,105 - TeleBot - ERROR - Infinity polling: polling exited
2025-09-20 11:21:44,106 - TeleBot - ERROR - Break infinity polling
2025-09-20 11:43:33,099 - TeleBot - ERROR - Infinity polling: polling exited
2025-09-20 11:43:33,099 - TeleBot - ERROR - Break infinity polling
2025-09-20 11:44:22,134 - TeleBot - ERROR - Infinity polling: polling exited
2025-09-20 11:44:22,134 - TeleBot - ERROR - Break infinity polling
2025-09-20 11:44:43,358 - TeleBot - ERROR - Infinity polling: polling exited
2025-09-20 11:44:43,359 - TeleBot - ERROR - Break infinity polling
2025-09-20 11:45:45,822 - TeleBot - ERROR - Infinity polling: polling exited
2025-09-20 11:45:45,822 - TeleBot - ERROR - Break infinity polling
2025-09-20 11:47:57,437 - TeleBot - ERROR - Infinity polling exception: ('Connection aborted.', RemoteDisconnected('Remote end closed connection without response'))
2025-09-20 11:47:57,451 - TeleBot - ERROR - Exception traceback:
Traceback (most recent call last):
  File "D:\Projects\TgBot\pythonProject1\.venv\Lib\site-packages\urllib3\connectionpool.py", line 787, in urlopen
    response = self._make_request(
               ^^^^^^^^^^^^^^^^^^^
  File "D:\Projects\TgBot\pythonProject1\.venv\Lib\site-packages\urllib3\connectionpool.py", line 534, in _make_request
    response = conn.getresponse()
               ^^^^^^^^^^^^^^^^^^
  File "D:\Projects\TgBot\pythonProject1\.venv\Lib\site-packages\urllib3\connection.py", line 565, in getresponse
    httplib_response = super().getresponse()
                       ^^^^^^^^^^^^^^^^^^^^^
  File "C:\Users\Ilya\AppData\Local\Programs\Python\Python312\Lib\http\client.py", line 1411, in getresponse
    response.begin()
  File "C:\Users\Ilya\AppData\Local\Programs\Python\Python312\Lib\http\client.py", line 324, in begin
    version, status, reason = self._read_status()
                              ^^^^^^^^^^^^^^^^^^^
  File "C:\Users\Ilya\AppData\Local\Programs\Python\Python312\Lib\http\client.py", line 293, in _read_status
    raise RemoteDisconnected("Remote end closed connection without"
http.client.RemoteDisconnected: Remote end closed connection without response

During handling of the above exception, another exception occurred:

Traceback (most recent call last):
  File "D:\Projects\TgBot\pythonProject1\.venv\Lib\site-packages\requests\adapters.py", line 644, in send
    resp = conn.urlopen(
           ^^^^^^^^^^^^^
  File "D:\Projects\TgBot\pythonProject1\.venv\Lib\site-packages\urllib3\connectionpool.py", line 841, in urlopen
    retries = retries.increment(
              ^^^^^^^^^^^^^^^^^^
  File "D:\Projects\TgBot\pythonProject1\.venv\Lib\site-packages\urllib3\util\retry.py", line 474, in increment
    raise reraise(type(error), error, _stacktrace)
          ^^^^^^^^^^^^^^^^^^^^^^^^^^^^^^^^^^^^^^^^
  File "D:\Projects\TgBot\pythonProject1\.venv\Lib\site-packages\urllib3\util\util.py", line 38, in reraise
    raise value.with_traceback(tb)
  File "D:\Projects\TgBot\pythonProject1\.venv\Lib\site-packages\urllib3\connectionpool.py", line 787, in urlopen
    response = self._make_request(
               ^^^^^^^^^^^^^^^^^^^
  File "D:\Projects\TgBot\pythonProject1\.venv\Lib\site-packages\urllib3\connectionpool.py", line 534, in _make_request
    response = conn.getresponse()
               ^^^^^^^^^^^^^^^^^^
  File "D:\Projects\TgBot\pythonProject1\.venv\Lib\site-packages\urllib3\connection.py", line 565, in getresponse
    httplib_response = super().getresponse()
                       ^^^^^^^^^^^^^^^^^^^^^
  File "C:\Users\Ilya\AppData\Local\Programs\Python\Python312\Lib\http\client.py", line 1411, in getresponse
    response.begin()
  File "C:\Users\Ilya\AppData\Local\Programs\Python\Python312\Lib\http\client.py", line 324, in begin
    version, status, reason = self._read_status()
                              ^^^^^^^^^^^^^^^^^^^
  File "C:\Users\Ilya\AppData\Local\Programs\Python\Python312\Lib\http\client.py", line 293, in _read_status
    raise RemoteDisconnected("Remote end closed connection without"
urllib3.exceptions.ProtocolError: ('Connection aborted.', RemoteDisconnected('Remote end closed connection without response'))

During handling of the above exception, another exception occurred:

Traceback (most recent call last):
  File "D:\Projects\TgBot\pythonProject1\.venv\Lib\site-packages\telebot\__init__.py", line 1110, in infinity_polling
    self.polling(non_stop=True, timeout=timeout, long_polling_timeout=long_polling_timeout,
  File "D:\Projects\TgBot\pythonProject1\.venv\Lib\site-packages\telebot\__init__.py", line 1198, in polling
    self.__threaded_polling(non_stop=non_stop, interval=interval, timeout=timeout, long_polling_timeout=long_polling_timeout,
  File "D:\Projects\TgBot\pythonProject1\.venv\Lib\site-packages\telebot\__init__.py", line 1273, in __threaded_polling
    raise e
  File "D:\Projects\TgBot\pythonProject1\.venv\Lib\site-packages\telebot\__init__.py", line 1234, in __threaded_polling
    polling_thread.raise_exceptions()
  File "D:\Projects\TgBot\pythonProject1\.venv\Lib\site-packages\telebot\util.py", line 115, in raise_exceptions
    raise self.exception_info
  File "D:\Projects\TgBot\pythonProject1\.venv\Lib\site-packages\telebot\util.py", line 97, in run
    task(*args, **kwargs)
  File "D:\Projects\TgBot\pythonProject1\.venv\Lib\site-packages\telebot\__init__.py", line 688, in __retrieve_updates
    updates = self.get_updates(offset=(self.last_update_id + 1),
              ^^^^^^^^^^^^^^^^^^^^^^^^^^^^^^^^^^^^^^^^^^^^^^^^^^
  File "D:\Projects\TgBot\pythonProject1\.venv\Lib\site-packages\telebot\__init__.py", line 660, in get_updates
    json_updates = apihelper.get_updates(
                   ^^^^^^^^^^^^^^^^^^^^^^
  File "D:\Projects\TgBot\pythonProject1\.venv\Lib\site-packages\telebot\apihelper.py", line 339, in get_updates
    return _make_request(token, method_url, params=payload)
           ^^^^^^^^^^^^^^^^^^^^^^^^^^^^^^^^^^^^^^^^^^^^^^^^
  File "D:\Projects\TgBot\pythonProject1\.venv\Lib\site-packages\telebot\apihelper.py", line 162, in _make_request
    result = _get_req_session().request(
             ^^^^^^^^^^^^^^^^^^^^^^^^^^^
  File "D:\Projects\TgBot\pythonProject1\.venv\Lib\site-packages\requests\sessions.py", line 589, in request
    resp = self.send(prep, **send_kwargs)
           ^^^^^^^^^^^^^^^^^^^^^^^^^^^^^^
  File "D:\Projects\TgBot\pythonProject1\.venv\Lib\site-packages\requests\sessions.py", line 703, in send
    r = adapter.send(request, **kwargs)
        ^^^^^^^^^^^^^^^^^^^^^^^^^^^^^^^
  File "D:\Projects\TgBot\pythonProject1\.venv\Lib\site-packages\requests\adapters.py", line 659, in send
    raise ConnectionError(err, request=request)
requests.exceptions.ConnectionError: ('Connection aborted.', RemoteDisconnected('Remote end closed connection without response'))

2025-09-20 12:17:03,831 - TeleBot - ERROR - Infinity polling exception: ('Connection aborted.', RemoteDisconnected('Remote end closed connection without response'))
2025-09-20 12:17:03,838 - TeleBot - ERROR - Exception traceback:
Traceback (most recent call last):
  File "D:\Projects\TgBot\pythonProject1\.venv\Lib\site-packages\urllib3\connectionpool.py", line 787, in urlopen
    response = self._make_request(
               ^^^^^^^^^^^^^^^^^^^
  File "D:\Projects\TgBot\pythonProject1\.venv\Lib\site-packages\urllib3\connectionpool.py", line 534, in _make_request
    response = conn.getresponse()
               ^^^^^^^^^^^^^^^^^^
  File "D:\Projects\TgBot\pythonProject1\.venv\Lib\site-packages\urllib3\connection.py", line 565, in getresponse
    httplib_response = super().getresponse()
                       ^^^^^^^^^^^^^^^^^^^^^
  File "C:\Users\Ilya\AppData\Local\Programs\Python\Python312\Lib\http\client.py", line 1411, in getresponse
    response.begin()
  File "C:\Users\Ilya\AppData\Local\Programs\Python\Python312\Lib\http\client.py", line 324, in begin
    version, status, reason = self._read_status()
                              ^^^^^^^^^^^^^^^^^^^
  File "C:\Users\Ilya\AppData\Local\Programs\Python\Python312\Lib\http\client.py", line 293, in _read_status
    raise RemoteDisconnected("Remote end closed connection without"
http.client.RemoteDisconnected: Remote end closed connection without response

During handling of the above exception, another exception occurred:

Traceback (most recent call last):
  File "D:\Projects\TgBot\pythonProject1\.venv\Lib\site-packages\requests\adapters.py", line 644, in send
    resp = conn.urlopen(
           ^^^^^^^^^^^^^
  File "D:\Projects\TgBot\pythonProject1\.venv\Lib\site-packages\urllib3\connectionpool.py", line 841, in urlopen
    retries = retries.increment(
              ^^^^^^^^^^^^^^^^^^
  File "D:\Projects\TgBot\pythonProject1\.venv\Lib\site-packages\urllib3\util\retry.py", line 474, in increment
    raise reraise(type(error), error, _stacktrace)
          ^^^^^^^^^^^^^^^^^^^^^^^^^^^^^^^^^^^^^^^^
  File "D:\Projects\TgBot\pythonProject1\.venv\Lib\site-packages\urllib3\util\util.py", line 38, in reraise
    raise value.with_traceback(tb)
  File "D:\Projects\TgBot\pythonProject1\.venv\Lib\site-packages\urllib3\connectionpool.py", line 787, in urlopen
    response = self._make_request(
               ^^^^^^^^^^^^^^^^^^^
  File "D:\Projects\TgBot\pythonProject1\.venv\Lib\site-packages\urllib3\connectionpool.py", line 534, in _make_request
    response = conn.getresponse()
               ^^^^^^^^^^^^^^^^^^
  File "D:\Projects\TgBot\pythonProject1\.venv\Lib\site-packages\urllib3\connection.py", line 565, in getresponse
    httplib_response = super().getresponse()
                       ^^^^^^^^^^^^^^^^^^^^^
  File "C:\Users\Ilya\AppData\Local\Programs\Python\Python312\Lib\http\client.py", line 1411, in getresponse
    response.begin()
  File "C:\Users\Ilya\AppData\Local\Programs\Python\Python312\Lib\http\client.py", line 324, in begin
    version, status, reason = self._read_status()
                              ^^^^^^^^^^^^^^^^^^^
  File "C:\Users\Ilya\AppData\Local\Programs\Python\Python312\Lib\http\client.py", line 293, in _read_status
    raise RemoteDisconnected("Remote end closed connection without"
urllib3.exceptions.ProtocolError: ('Connection aborted.', RemoteDisconnected('Remote end closed connection without response'))

During handling of the above exception, another exception occurred:

Traceback (most recent call last):
  File "D:\Projects\TgBot\pythonProject1\.venv\Lib\site-packages\telebot\__init__.py", line 1110, in infinity_polling
    self.polling(non_stop=True, timeout=timeout, long_polling_timeout=long_polling_timeout,
  File "D:\Projects\TgBot\pythonProject1\.venv\Lib\site-packages\telebot\__init__.py", line 1198, in polling
    self.__threaded_polling(non_stop=non_stop, interval=interval, timeout=timeout, long_polling_timeout=long_polling_timeout,
  File "D:\Projects\TgBot\pythonProject1\.venv\Lib\site-packages\telebot\__init__.py", line 1273, in __threaded_polling
    raise e
  File "D:\Projects\TgBot\pythonProject1\.venv\Lib\site-packages\telebot\__init__.py", line 1234, in __threaded_polling
    polling_thread.raise_exceptions()
  File "D:\Projects\TgBot\pythonProject1\.venv\Lib\site-packages\telebot\util.py", line 115, in raise_exceptions
    raise self.exception_info
  File "D:\Projects\TgBot\pythonProject1\.venv\Lib\site-packages\telebot\util.py", line 97, in run
    task(*args, **kwargs)
  File "D:\Projects\TgBot\pythonProject1\.venv\Lib\site-packages\telebot\__init__.py", line 688, in __retrieve_updates
    updates = self.get_updates(offset=(self.last_update_id + 1),
              ^^^^^^^^^^^^^^^^^^^^^^^^^^^^^^^^^^^^^^^^^^^^^^^^^^
  File "D:\Projects\TgBot\pythonProject1\.venv\Lib\site-packages\telebot\__init__.py", line 660, in get_updates
    json_updates = apihelper.get_updates(
                   ^^^^^^^^^^^^^^^^^^^^^^
  File "D:\Projects\TgBot\pythonProject1\.venv\Lib\site-packages\telebot\apihelper.py", line 339, in get_updates
    return _make_request(token, method_url, params=payload)
           ^^^^^^^^^^^^^^^^^^^^^^^^^^^^^^^^^^^^^^^^^^^^^^^^
  File "D:\Projects\TgBot\pythonProject1\.venv\Lib\site-packages\telebot\apihelper.py", line 162, in _make_request
    result = _get_req_session().request(
             ^^^^^^^^^^^^^^^^^^^^^^^^^^^
  File "D:\Projects\TgBot\pythonProject1\.venv\Lib\site-packages\requests\sessions.py", line 589, in request
    resp = self.send(prep, **send_kwargs)
           ^^^^^^^^^^^^^^^^^^^^^^^^^^^^^^
  File "D:\Projects\TgBot\pythonProject1\.venv\Lib\site-packages\requests\sessions.py", line 703, in send
    r = adapter.send(request, **kwargs)
        ^^^^^^^^^^^^^^^^^^^^^^^^^^^^^^^
  File "D:\Projects\TgBot\pythonProject1\.venv\Lib\site-packages\requests\adapters.py", line 659, in send
    raise ConnectionError(err, request=request)
requests.exceptions.ConnectionError: ('Connection aborted.', RemoteDisconnected('Remote end closed connection without response'))

2025-09-20 12:17:06,950 - TeleBot - ERROR - Infinity polling exception: HTTPSConnectionPool(host='api.telegram.org', port=443): Max retries exceeded with url: /bot8417941208:***********************************/getUpdates?offset=34701296&timeout=20 (Caused by NameResolutionError("<urllib3.connection.HTTPSConnection object at 0x00000239E2C43920>: Failed to resolve 'api.telegram.org' ([Errno 11001] getaddrinfo failed)"))
2025-09-20 12:17:06,953 - TeleBot - ERROR - Exception traceback:
Traceback (most recent call last):
  File "D:\Projects\TgBot\pythonProject1\.venv\Lib\site-packages\urllib3\connection.py", line 198, in _new_conn
    sock = connection.create_connection(
           ^^^^^^^^^^^^^^^^^^^^^^^^^^^^^
  File "D:\Projects\TgBot\pythonProject1\.venv\Lib\site-packages\urllib3\util\connection.py", line 60, in create_connection
    for res in socket.getaddrinfo(host, port, family, socket.SOCK_STREAM):
               ^^^^^^^^^^^^^^^^^^^^^^^^^^^^^^^^^^^^^^^^^^^^^^^^^^^^^^^^^^
  File "C:\Users\Ilya\AppData\Local\Programs\Python\Python312\Lib\socket.py", line 963, in getaddrinfo
    for res in _socket.getaddrinfo(host, port, family, type, proto, flags):
               ^^^^^^^^^^^^^^^^^^^^^^^^^^^^^^^^^^^^^^^^^^^^^^^^^^^^^^^^^^^
socket.gaierror: [Errno 11001] getaddrinfo failed

The above exception was the direct cause of the following exception:

Traceback (most recent call last):
  File "D:\Projects\TgBot\pythonProject1\.venv\Lib\site-packages\urllib3\connectionpool.py", line 787, in urlopen
    response = self._make_request(
               ^^^^^^^^^^^^^^^^^^^
  File "D:\Projects\TgBot\pythonProject1\.venv\Lib\site-packages\urllib3\connectionpool.py", line 488, in _make_request
    raise new_e
  File "D:\Projects\TgBot\pythonProject1\.venv\Lib\site-packages\urllib3\connectionpool.py", line 464, in _make_request
    self._validate_conn(conn)
  File "D:\Projects\TgBot\pythonProject1\.venv\Lib\site-packages\urllib3\connectionpool.py", line 1093, in _validate_conn
    conn.connect()
  File "D:\Projects\TgBot\pythonProject1\.venv\Lib\site-packages\urllib3\connection.py", line 753, in connect
    self.sock = sock = self._new_conn()
                       ^^^^^^^^^^^^^^^^
  File "D:\Projects\TgBot\pythonProject1\.venv\Lib\site-packages\urllib3\connection.py", line 205, in _new_conn
    raise NameResolutionError(self.host, self, e) from e
urllib3.exceptions.NameResolutionError: <urllib3.connection.HTTPSConnection object at 0x00000239E2C43920>: Failed to resolve 'api.telegram.org' ([Errno 11001] getaddrinfo failed)

The above exception was the direct cause of the following exception:

Traceback (most recent call last):
  File "D:\Projects\TgBot\pythonProject1\.venv\Lib\site-packages\requests\adapters.py", line 644, in send
    resp = conn.urlopen(
           ^^^^^^^^^^^^^
  File "D:\Projects\TgBot\pythonProject1\.venv\Lib\site-packages\urllib3\connectionpool.py", line 841, in urlopen
    retries = retries.increment(
              ^^^^^^^^^^^^^^^^^^
  File "D:\Projects\TgBot\pythonProject1\.venv\Lib\site-packages\urllib3\util\retry.py", line 519, in increment
    raise MaxRetryError(_pool, url, reason) from reason  # type: ignore[arg-type]
    ^^^^^^^^^^^^^^^^^^^^^^^^^^^^^^^^^^^^^^^^^^^^^^^^^^^
urllib3.exceptions.MaxRetryError: HTTPSConnectionPool(host='api.telegram.org', port=443): Max retries exceeded with url: /bot8417941208:***********************************/getUpdates?offset=34701296&timeout=20 (Caused by NameResolutionError("<urllib3.connection.HTTPSConnection object at 0x00000239E2C43920>: Failed to resolve 'api.telegram.org' ([Errno 11001] getaddrinfo failed)"))

During handling of the above exception, another exception occurred:

Traceback (most recent call last):
  File "D:\Projects\TgBot\pythonProject1\.venv\Lib\site-packages\telebot\__init__.py", line 1110, in infinity_polling
    self.polling(non_stop=True, timeout=timeout, long_polling_timeout=long_polling_timeout,
  File "D:\Projects\TgBot\pythonProject1\.venv\Lib\site-packages\telebot\__init__.py", line 1198, in polling
    self.__threaded_polling(non_stop=non_stop, interval=interval, timeout=timeout, long_polling_timeout=long_polling_timeout,
  File "D:\Projects\TgBot\pythonProject1\.venv\Lib\site-packages\telebot\__init__.py", line 1273, in __threaded_polling
    raise e
  File "D:\Projects\TgBot\pythonProject1\.venv\Lib\site-packages\telebot\__init__.py", line 1234, in __threaded_polling
    polling_thread.raise_exceptions()
  File "D:\Projects\TgBot\pythonProject1\.venv\Lib\site-packages\telebot\util.py", line 115, in raise_exceptions
    raise self.exception_info
  File "D:\Projects\TgBot\pythonProject1\.venv\Lib\site-packages\telebot\util.py", line 97, in run
    task(*args, **kwargs)
  File "D:\Projects\TgBot\pythonProject1\.venv\Lib\site-packages\telebot\__init__.py", line 688, in __retrieve_updates
    updates = self.get_updates(offset=(self.last_update_id + 1),
              ^^^^^^^^^^^^^^^^^^^^^^^^^^^^^^^^^^^^^^^^^^^^^^^^^^
  File "D:\Projects\TgBot\pythonProject1\.venv\Lib\site-packages\telebot\__init__.py", line 660, in get_updates
    json_updates = apihelper.get_updates(
                   ^^^^^^^^^^^^^^^^^^^^^^
  File "D:\Projects\TgBot\pythonProject1\.venv\Lib\site-packages\telebot\apihelper.py", line 339, in get_updates
    return _make_request(token, method_url, params=payload)
           ^^^^^^^^^^^^^^^^^^^^^^^^^^^^^^^^^^^^^^^^^^^^^^^^
  File "D:\Projects\TgBot\pythonProject1\.venv\Lib\site-packages\telebot\apihelper.py", line 162, in _make_request
    result = _get_req_session().request(
             ^^^^^^^^^^^^^^^^^^^^^^^^^^^
  File "D:\Projects\TgBot\pythonProject1\.venv\Lib\site-packages\requests\sessions.py", line 589, in request
    resp = self.send(prep, **send_kwargs)
           ^^^^^^^^^^^^^^^^^^^^^^^^^^^^^^
  File "D:\Projects\TgBot\pythonProject1\.venv\Lib\site-packages\requests\sessions.py", line 703, in send
    r = adapter.send(request, **kwargs)
        ^^^^^^^^^^^^^^^^^^^^^^^^^^^^^^^
  File "D:\Projects\TgBot\pythonProject1\.venv\Lib\site-packages\requests\adapters.py", line 677, in send
    raise ConnectionError(e, request=request)
requests.exceptions.ConnectionError: HTTPSConnectionPool(host='api.telegram.org', port=443): Max retries exceeded with url: /bot8417941208:***********************************/getUpdates?offset=34701296&timeout=20 (Caused by NameResolutionError("<urllib3.connection.HTTPSConnection object at 0x00000239E2C43920>: Failed to resolve 'api.telegram.org' ([Errno 11001] getaddrinfo failed)"))

2025-09-20 12:57:09,958 - TeleBot - ERROR - Infinity polling exception: HTTPSConnectionPool(host='api.telegram.org', port=443): Max retries exceeded with url: /bot8417941208:***********************************/getUpdates?offset=34701296&timeout=20 (Caused by NameResolutionError("<urllib3.connection.HTTPSConnection object at 0x00000239E2C0AAB0>: Failed to resolve 'api.telegram.org' ([Errno 11001] getaddrinfo failed)"))
2025-09-20 12:57:09,963 - TeleBot - ERROR - Exception traceback:
Traceback (most recent call last):
  File "D:\Projects\TgBot\pythonProject1\.venv\Lib\site-packages\urllib3\connection.py", line 198, in _new_conn
    sock = connection.create_connection(
           ^^^^^^^^^^^^^^^^^^^^^^^^^^^^^
  File "D:\Projects\TgBot\pythonProject1\.venv\Lib\site-packages\urllib3\util\connection.py", line 60, in create_connection
    for res in socket.getaddrinfo(host, port, family, socket.SOCK_STREAM):
               ^^^^^^^^^^^^^^^^^^^^^^^^^^^^^^^^^^^^^^^^^^^^^^^^^^^^^^^^^^
  File "C:\Users\Ilya\AppData\Local\Programs\Python\Python312\Lib\socket.py", line 963, in getaddrinfo
    for res in _socket.getaddrinfo(host, port, family, type, proto, flags):
               ^^^^^^^^^^^^^^^^^^^^^^^^^^^^^^^^^^^^^^^^^^^^^^^^^^^^^^^^^^^
socket.gaierror: [Errno 11001] getaddrinfo failed

The above exception was the direct cause of the following exception:

Traceback (most recent call last):
  File "D:\Projects\TgBot\pythonProject1\.venv\Lib\site-packages\urllib3\connectionpool.py", line 787, in urlopen
    response = self._make_request(
               ^^^^^^^^^^^^^^^^^^^
  File "D:\Projects\TgBot\pythonProject1\.venv\Lib\site-packages\urllib3\connectionpool.py", line 488, in _make_request
    raise new_e
  File "D:\Projects\TgBot\pythonProject1\.venv\Lib\site-packages\urllib3\connectionpool.py", line 464, in _make_request
    self._validate_conn(conn)
  File "D:\Projects\TgBot\pythonProject1\.venv\Lib\site-packages\urllib3\connectionpool.py", line 1093, in _validate_conn
    conn.connect()
  File "D:\Projects\TgBot\pythonProject1\.venv\Lib\site-packages\urllib3\connection.py", line 753, in connect
    self.sock = sock = self._new_conn()
                       ^^^^^^^^^^^^^^^^
  File "D:\Projects\TgBot\pythonProject1\.venv\Lib\site-packages\urllib3\connection.py", line 205, in _new_conn
    raise NameResolutionError(self.host, self, e) from e
urllib3.exceptions.NameResolutionError: <urllib3.connection.HTTPSConnection object at 0x00000239E2C0AAB0>: Failed to resolve 'api.telegram.org' ([Errno 11001] getaddrinfo failed)

The above exception was the direct cause of the following exception:

Traceback (most recent call last):
  File "D:\Projects\TgBot\pythonProject1\.venv\Lib\site-packages\requests\adapters.py", line 644, in send
    resp = conn.urlopen(
           ^^^^^^^^^^^^^
  File "D:\Projects\TgBot\pythonProject1\.venv\Lib\site-packages\urllib3\connectionpool.py", line 841, in urlopen
    retries = retries.increment(
              ^^^^^^^^^^^^^^^^^^
  File "D:\Projects\TgBot\pythonProject1\.venv\Lib\site-packages\urllib3\util\retry.py", line 519, in increment
    raise MaxRetryError(_pool, url, reason) from reason  # type: ignore[arg-type]
    ^^^^^^^^^^^^^^^^^^^^^^^^^^^^^^^^^^^^^^^^^^^^^^^^^^^
urllib3.exceptions.MaxRetryError: HTTPSConnectionPool(host='api.telegram.org', port=443): Max retries exceeded with url: /bot8417941208:***********************************/getUpdates?offset=34701296&timeout=20 (Caused by NameResolutionError("<urllib3.connection.HTTPSConnection object at 0x00000239E2C0AAB0>: Failed to resolve 'api.telegram.org' ([Errno 11001] getaddrinfo failed)"))

During handling of the above exception, another exception occurred:

Traceback (most recent call last):
  File "D:\Projects\TgBot\pythonProject1\.venv\Lib\site-packages\telebot\__init__.py", line 1110, in infinity_polling
    self.polling(non_stop=True, timeout=timeout, long_polling_timeout=long_polling_timeout,
  File "D:\Projects\TgBot\pythonProject1\.venv\Lib\site-packages\telebot\__init__.py", line 1198, in polling
    self.__threaded_polling(non_stop=non_stop, interval=interval, timeout=timeout, long_polling_timeout=long_polling_timeout,
  File "D:\Projects\TgBot\pythonProject1\.venv\Lib\site-packages\telebot\__init__.py", line 1273, in __threaded_polling
    raise e
  File "D:\Projects\TgBot\pythonProject1\.venv\Lib\site-packages\telebot\__init__.py", line 1234, in __threaded_polling
    polling_thread.raise_exceptions()
  File "D:\Projects\TgBot\pythonProject1\.venv\Lib\site-packages\telebot\util.py", line 115, in raise_exceptions
    raise self.exception_info
  File "D:\Projects\TgBot\pythonProject1\.venv\Lib\site-packages\telebot\util.py", line 97, in run
    task(*args, **kwargs)
  File "D:\Projects\TgBot\pythonProject1\.venv\Lib\site-packages\telebot\__init__.py", line 688, in __retrieve_updates
    updates = self.get_updates(offset=(self.last_update_id + 1),
              ^^^^^^^^^^^^^^^^^^^^^^^^^^^^^^^^^^^^^^^^^^^^^^^^^^
  File "D:\Projects\TgBot\pythonProject1\.venv\Lib\site-packages\telebot\__init__.py", line 660, in get_updates
    json_updates = apihelper.get_updates(
                   ^^^^^^^^^^^^^^^^^^^^^^
  File "D:\Projects\TgBot\pythonProject1\.venv\Lib\site-packages\telebot\apihelper.py", line 339, in get_updates
    return _make_request(token, method_url, params=payload)
           ^^^^^^^^^^^^^^^^^^^^^^^^^^^^^^^^^^^^^^^^^^^^^^^^
  File "D:\Projects\TgBot\pythonProject1\.venv\Lib\site-packages\telebot\apihelper.py", line 162, in _make_request
    result = _get_req_session().request(
             ^^^^^^^^^^^^^^^^^^^^^^^^^^^
  File "D:\Projects\TgBot\pythonProject1\.venv\Lib\site-packages\requests\sessions.py", line 589, in request
    resp = self.send(prep, **send_kwargs)
           ^^^^^^^^^^^^^^^^^^^^^^^^^^^^^^
  File "D:\Projects\TgBot\pythonProject1\.venv\Lib\site-packages\requests\sessions.py", line 703, in send
    r = adapter.send(request, **kwargs)
        ^^^^^^^^^^^^^^^^^^^^^^^^^^^^^^^
  File "D:\Projects\TgBot\pythonProject1\.venv\Lib\site-packages\requests\adapters.py", line 677, in send
    raise ConnectionError(e, request=request)
requests.exceptions.ConnectionError: HTTPSConnectionPool(host='api.telegram.org', port=443): Max retries exceeded with url: /bot8417941208:***********************************/getUpdates?offset=34701296&timeout=20 (Caused by NameResolutionError("<urllib3.connection.HTTPSConnection object at 0x00000239E2C0AAB0>: Failed to resolve 'api.telegram.org' ([Errno 11001] getaddrinfo failed)"))

2025-09-20 12:57:13,003 - TeleBot - ERROR - Infinity polling exception: HTTPSConnectionPool(host='api.telegram.org', port=443): Max retries exceeded with url: /bot8417941208:***********************************/getUpdates?offset=34701296&timeout=20 (Caused by NameResolutionError("<urllib3.connection.HTTPSConnection object at 0x00000239E2C42B70>: Failed to resolve 'api.telegram.org' ([Errno 11001] getaddrinfo failed)"))
2025-09-20 12:57:13,006 - TeleBot - ERROR - Exception traceback:
Traceback (most recent call last):
  File "D:\Projects\TgBot\pythonProject1\.venv\Lib\site-packages\urllib3\connection.py", line 198, in _new_conn
    sock = connection.create_connection(
           ^^^^^^^^^^^^^^^^^^^^^^^^^^^^^
  File "D:\Projects\TgBot\pythonProject1\.venv\Lib\site-packages\urllib3\util\connection.py", line 60, in create_connection
    for res in socket.getaddrinfo(host, port, family, socket.SOCK_STREAM):
               ^^^^^^^^^^^^^^^^^^^^^^^^^^^^^^^^^^^^^^^^^^^^^^^^^^^^^^^^^^
  File "C:\Users\Ilya\AppData\Local\Programs\Python\Python312\Lib\socket.py", line 963, in getaddrinfo
    for res in _socket.getaddrinfo(host, port, family, type, proto, flags):
               ^^^^^^^^^^^^^^^^^^^^^^^^^^^^^^^^^^^^^^^^^^^^^^^^^^^^^^^^^^^
socket.gaierror: [Errno 11001] getaddrinfo failed

The above exception was the direct cause of the following exception:

Traceback (most recent call last):
  File "D:\Projects\TgBot\pythonProject1\.venv\Lib\site-packages\urllib3\connectionpool.py", line 787, in urlopen
    response = self._make_request(
               ^^^^^^^^^^^^^^^^^^^
  File "D:\Projects\TgBot\pythonProject1\.venv\Lib\site-packages\urllib3\connectionpool.py", line 488, in _make_request
    raise new_e
  File "D:\Projects\TgBot\pythonProject1\.venv\Lib\site-packages\urllib3\connectionpool.py", line 464, in _make_request
    self._validate_conn(conn)
  File "D:\Projects\TgBot\pythonProject1\.venv\Lib\site-packages\urllib3\connectionpool.py", line 1093, in _validate_conn
    conn.connect()
  File "D:\Projects\TgBot\pythonProject1\.venv\Lib\site-packages\urllib3\connection.py", line 753, in connect
    self.sock = sock = self._new_conn()
                       ^^^^^^^^^^^^^^^^
  File "D:\Projects\TgBot\pythonProject1\.venv\Lib\site-packages\urllib3\connection.py", line 205, in _new_conn
    raise NameResolutionError(self.host, self, e) from e
urllib3.exceptions.NameResolutionError: <urllib3.connection.HTTPSConnection object at 0x00000239E2C42B70>: Failed to resolve 'api.telegram.org' ([Errno 11001] getaddrinfo failed)

The above exception was the direct cause of the following exception:

Traceback (most recent call last):
  File "D:\Projects\TgBot\pythonProject1\.venv\Lib\site-packages\requests\adapters.py", line 644, in send
    resp = conn.urlopen(
           ^^^^^^^^^^^^^
  File "D:\Projects\TgBot\pythonProject1\.venv\Lib\site-packages\urllib3\connectionpool.py", line 841, in urlopen
    retries = retries.increment(
              ^^^^^^^^^^^^^^^^^^
  File "D:\Projects\TgBot\pythonProject1\.venv\Lib\site-packages\urllib3\util\retry.py", line 519, in increment
    raise MaxRetryError(_pool, url, reason) from reason  # type: ignore[arg-type]
    ^^^^^^^^^^^^^^^^^^^^^^^^^^^^^^^^^^^^^^^^^^^^^^^^^^^
urllib3.exceptions.MaxRetryError: HTTPSConnectionPool(host='api.telegram.org', port=443): Max retries exceeded with url: /bot8417941208:***********************************/getUpdates?offset=34701296&timeout=20 (Caused by NameResolutionError("<urllib3.connection.HTTPSConnection object at 0x00000239E2C42B70>: Failed to resolve 'api.telegram.org' ([Errno 11001] getaddrinfo failed)"))

During handling of the above exception, another exception occurred:

Traceback (most recent call last):
  File "D:\Projects\TgBot\pythonProject1\.venv\Lib\site-packages\telebot\__init__.py", line 1110, in infinity_polling
    self.polling(non_stop=True, timeout=timeout, long_polling_timeout=long_polling_timeout,
  File "D:\Projects\TgBot\pythonProject1\.venv\Lib\site-packages\telebot\__init__.py", line 1198, in polling
    self.__threaded_polling(non_stop=non_stop, interval=interval, timeout=timeout, long_polling_timeout=long_polling_timeout,
  File "D:\Projects\TgBot\pythonProject1\.venv\Lib\site-packages\telebot\__init__.py", line 1273, in __threaded_polling
    raise e
  File "D:\Projects\TgBot\pythonProject1\.venv\Lib\site-packages\telebot\__init__.py", line 1234, in __threaded_polling
    polling_thread.raise_exceptions()
  File "D:\Projects\TgBot\pythonProject1\.venv\Lib\site-packages\telebot\util.py", line 115, in raise_exceptions
    raise self.exception_info
  File "D:\Projects\TgBot\pythonProject1\.venv\Lib\site-packages\telebot\util.py", line 97, in run
    task(*args, **kwargs)
  File "D:\Projects\TgBot\pythonProject1\.venv\Lib\site-packages\telebot\__init__.py", line 688, in __retrieve_updates
    updates = self.get_updates(offset=(self.last_update_id + 1),
              ^^^^^^^^^^^^^^^^^^^^^^^^^^^^^^^^^^^^^^^^^^^^^^^^^^
  File "D:\Projects\TgBot\pythonProject1\.venv\Lib\site-packages\telebot\__init__.py", line 660, in get_updates
    json_updates = apihelper.get_updates(
                   ^^^^^^^^^^^^^^^^^^^^^^
  File "D:\Projects\TgBot\pythonProject1\.venv\Lib\site-packages\telebot\apihelper.py", line 339, in get_updates
    return _make_request(token, method_url, params=payload)
           ^^^^^^^^^^^^^^^^^^^^^^^^^^^^^^^^^^^^^^^^^^^^^^^^
  File "D:\Projects\TgBot\pythonProject1\.venv\Lib\site-packages\telebot\apihelper.py", line 162, in _make_request
    result = _get_req_session().request(
             ^^^^^^^^^^^^^^^^^^^^^^^^^^^
  File "D:\Projects\TgBot\pythonProject1\.venv\Lib\site-packages\requests\sessions.py", line 589, in request
    resp = self.send(prep, **send_kwargs)
           ^^^^^^^^^^^^^^^^^^^^^^^^^^^^^^
  File "D:\Projects\TgBot\pythonProject1\.venv\Lib\site-packages\requests\sessions.py", line 703, in send
    r = adapter.send(request, **kwargs)
        ^^^^^^^^^^^^^^^^^^^^^^^^^^^^^^^
  File "D:\Projects\TgBot\pythonProject1\.venv\Lib\site-packages\requests\adapters.py", line 677, in send
    raise ConnectionError(e, request=request)
requests.exceptions.ConnectionError: HTTPSConnectionPool(host='api.telegram.org', port=443): Max retries exceeded with url: /bot8417941208:***********************************/getUpdates?offset=34701296&timeout=20 (Caused by NameResolutionError("<urllib3.connection.HTTPSConnection object at 0x00000239E2C42B70>: Failed to resolve 'api.telegram.org' ([Errno 11001] getaddrinfo failed)"))

2025-09-20 12:59:55,013 - TeleBot - ERROR - Infinity polling exception: HTTPSConnectionPool(host='api.telegram.org', port=443): Max retries exceeded with url: /bot8417941208:***********************************/getUpdates?offset=34701296&timeout=20 (Caused by NameResolutionError("<urllib3.connection.HTTPSConnection object at 0x00000239E316CB00>: Failed to resolve 'api.telegram.org' ([Errno 11001] getaddrinfo failed)"))
2025-09-20 12:59:55,017 - TeleBot - ERROR - Exception traceback:
Traceback (most recent call last):
  File "D:\Projects\TgBot\pythonProject1\.venv\Lib\site-packages\urllib3\connection.py", line 198, in _new_conn
    sock = connection.create_connection(
           ^^^^^^^^^^^^^^^^^^^^^^^^^^^^^
  File "D:\Projects\TgBot\pythonProject1\.venv\Lib\site-packages\urllib3\util\connection.py", line 60, in create_connection
    for res in socket.getaddrinfo(host, port, family, socket.SOCK_STREAM):
               ^^^^^^^^^^^^^^^^^^^^^^^^^^^^^^^^^^^^^^^^^^^^^^^^^^^^^^^^^^
  File "C:\Users\Ilya\AppData\Local\Programs\Python\Python312\Lib\socket.py", line 963, in getaddrinfo
    for res in _socket.getaddrinfo(host, port, family, type, proto, flags):
               ^^^^^^^^^^^^^^^^^^^^^^^^^^^^^^^^^^^^^^^^^^^^^^^^^^^^^^^^^^^
socket.gaierror: [Errno 11001] getaddrinfo failed

The above exception was the direct cause of the following exception:

Traceback (most recent call last):
  File "D:\Projects\TgBot\pythonProject1\.venv\Lib\site-packages\urllib3\connectionpool.py", line 787, in urlopen
    response = self._make_request(
               ^^^^^^^^^^^^^^^^^^^
  File "D:\Projects\TgBot\pythonProject1\.venv\Lib\site-packages\urllib3\connectionpool.py", line 488, in _make_request
    raise new_e
  File "D:\Projects\TgBot\pythonProject1\.venv\Lib\site-packages\urllib3\connectionpool.py", line 464, in _make_request
    self._validate_conn(conn)
  File "D:\Projects\TgBot\pythonProject1\.venv\Lib\site-packages\urllib3\connectionpool.py", line 1093, in _validate_conn
    conn.connect()
  File "D:\Projects\TgBot\pythonProject1\.venv\Lib\site-packages\urllib3\connection.py", line 753, in connect
    self.sock = sock = self._new_conn()
                       ^^^^^^^^^^^^^^^^
  File "D:\Projects\TgBot\pythonProject1\.venv\Lib\site-packages\urllib3\connection.py", line 205, in _new_conn
    raise NameResolutionError(self.host, self, e) from e
urllib3.exceptions.NameResolutionError: <urllib3.connection.HTTPSConnection object at 0x00000239E316CB00>: Failed to resolve 'api.telegram.org' ([Errno 11001] getaddrinfo failed)

The above exception was the direct cause of the following exception:

Traceback (most recent call last):
  File "D:\Projects\TgBot\pythonProject1\.venv\Lib\site-packages\requests\adapters.py", line 644, in send
    resp = conn.urlopen(
           ^^^^^^^^^^^^^
  File "D:\Projects\TgBot\pythonProject1\.venv\Lib\site-packages\urllib3\connectionpool.py", line 841, in urlopen
    retries = retries.increment(
              ^^^^^^^^^^^^^^^^^^
  File "D:\Projects\TgBot\pythonProject1\.venv\Lib\site-packages\urllib3\util\retry.py", line 519, in increment
    raise MaxRetryError(_pool, url, reason) from reason  # type: ignore[arg-type]
    ^^^^^^^^^^^^^^^^^^^^^^^^^^^^^^^^^^^^^^^^^^^^^^^^^^^
urllib3.exceptions.MaxRetryError: HTTPSConnectionPool(host='api.telegram.org', port=443): Max retries exceeded with url: /bot8417941208:***********************************/getUpdates?offset=34701296&timeout=20 (Caused by NameResolutionError("<urllib3.connection.HTTPSConnection object at 0x00000239E316CB00>: Failed to resolve 'api.telegram.org' ([Errno 11001] getaddrinfo failed)"))

During handling of the above exception, another exception occurred:

Traceback (most recent call last):
  File "D:\Projects\TgBot\pythonProject1\.venv\Lib\site-packages\telebot\__init__.py", line 1110, in infinity_polling
    self.polling(non_stop=True, timeout=timeout, long_polling_timeout=long_polling_timeout,
  File "D:\Projects\TgBot\pythonProject1\.venv\Lib\site-packages\telebot\__init__.py", line 1198, in polling
    self.__threaded_polling(non_stop=non_stop, interval=interval, timeout=timeout, long_polling_timeout=long_polling_timeout,
  File "D:\Projects\TgBot\pythonProject1\.venv\Lib\site-packages\telebot\__init__.py", line 1273, in __threaded_polling
    raise e
  File "D:\Projects\TgBot\pythonProject1\.venv\Lib\site-packages\telebot\__init__.py", line 1234, in __threaded_polling
    polling_thread.raise_exceptions()
  File "D:\Projects\TgBot\pythonProject1\.venv\Lib\site-packages\telebot\util.py", line 115, in raise_exceptions
    raise self.exception_info
  File "D:\Projects\TgBot\pythonProject1\.venv\Lib\site-packages\telebot\util.py", line 97, in run
    task(*args, **kwargs)
  File "D:\Projects\TgBot\pythonProject1\.venv\Lib\site-packages\telebot\__init__.py", line 688, in __retrieve_updates
    updates = self.get_updates(offset=(self.last_update_id + 1),
              ^^^^^^^^^^^^^^^^^^^^^^^^^^^^^^^^^^^^^^^^^^^^^^^^^^
  File "D:\Projects\TgBot\pythonProject1\.venv\Lib\site-packages\telebot\__init__.py", line 660, in get_updates
    json_updates = apihelper.get_updates(
                   ^^^^^^^^^^^^^^^^^^^^^^
  File "D:\Projects\TgBot\pythonProject1\.venv\Lib\site-packages\telebot\apihelper.py", line 339, in get_updates
    return _make_request(token, method_url, params=payload)
           ^^^^^^^^^^^^^^^^^^^^^^^^^^^^^^^^^^^^^^^^^^^^^^^^
  File "D:\Projects\TgBot\pythonProject1\.venv\Lib\site-packages\telebot\apihelper.py", line 162, in _make_request
    result = _get_req_session().request(
             ^^^^^^^^^^^^^^^^^^^^^^^^^^^
  File "D:\Projects\TgBot\pythonProject1\.venv\Lib\site-packages\requests\sessions.py", line 589, in request
    resp = self.send(prep, **send_kwargs)
           ^^^^^^^^^^^^^^^^^^^^^^^^^^^^^^
  File "D:\Projects\TgBot\pythonProject1\.venv\Lib\site-packages\requests\sessions.py", line 703, in send
    r = adapter.send(request, **kwargs)
        ^^^^^^^^^^^^^^^^^^^^^^^^^^^^^^^
  File "D:\Projects\TgBot\pythonProject1\.venv\Lib\site-packages\requests\adapters.py", line 677, in send
    raise ConnectionError(e, request=request)
requests.exceptions.ConnectionError: HTTPSConnectionPool(host='api.telegram.org', port=443): Max retries exceeded with url: /bot8417941208:***********************************/getUpdates?offset=34701296&timeout=20 (Caused by NameResolutionError("<urllib3.connection.HTTPSConnection object at 0x00000239E316CB00>: Failed to resolve 'api.telegram.org' ([Errno 11001] getaddrinfo failed)"))

2025-09-20 12:59:58,047 - TeleBot - ERROR - Infinity polling exception: HTTPSConnectionPool(host='api.telegram.org', port=443): Max retries exceeded with url: /bot8417941208:***********************************/getUpdates?offset=34701296&timeout=20 (Caused by NameResolutionError("<urllib3.connection.HTTPSConnection object at 0x00000239E316DC40>: Failed to resolve 'api.telegram.org' ([Errno 11001] getaddrinfo failed)"))
2025-09-20 12:59:58,050 - TeleBot - ERROR - Exception traceback:
Traceback (most recent call last):
  File "D:\Projects\TgBot\pythonProject1\.venv\Lib\site-packages\urllib3\connection.py", line 198, in _new_conn
    sock = connection.create_connection(
           ^^^^^^^^^^^^^^^^^^^^^^^^^^^^^
  File "D:\Projects\TgBot\pythonProject1\.venv\Lib\site-packages\urllib3\util\connection.py", line 60, in create_connection
    for res in socket.getaddrinfo(host, port, family, socket.SOCK_STREAM):
               ^^^^^^^^^^^^^^^^^^^^^^^^^^^^^^^^^^^^^^^^^^^^^^^^^^^^^^^^^^
  File "C:\Users\Ilya\AppData\Local\Programs\Python\Python312\Lib\socket.py", line 963, in getaddrinfo
    for res in _socket.getaddrinfo(host, port, family, type, proto, flags):
               ^^^^^^^^^^^^^^^^^^^^^^^^^^^^^^^^^^^^^^^^^^^^^^^^^^^^^^^^^^^
socket.gaierror: [Errno 11001] getaddrinfo failed

The above exception was the direct cause of the following exception:

Traceback (most recent call last):
  File "D:\Projects\TgBot\pythonProject1\.venv\Lib\site-packages\urllib3\connectionpool.py", line 787, in urlopen
    response = self._make_request(
               ^^^^^^^^^^^^^^^^^^^
  File "D:\Projects\TgBot\pythonProject1\.venv\Lib\site-packages\urllib3\connectionpool.py", line 488, in _make_request
    raise new_e
  File "D:\Projects\TgBot\pythonProject1\.venv\Lib\site-packages\urllib3\connectionpool.py", line 464, in _make_request
    self._validate_conn(conn)
  File "D:\Projects\TgBot\pythonProject1\.venv\Lib\site-packages\urllib3\connectionpool.py", line 1093, in _validate_conn
    conn.connect()
  File "D:\Projects\TgBot\pythonProject1\.venv\Lib\site-packages\urllib3\connection.py", line 753, in connect
    self.sock = sock = self._new_conn()
                       ^^^^^^^^^^^^^^^^
  File "D:\Projects\TgBot\pythonProject1\.venv\Lib\site-packages\urllib3\connection.py", line 205, in _new_conn
    raise NameResolutionError(self.host, self, e) from e
urllib3.exceptions.NameResolutionError: <urllib3.connection.HTTPSConnection object at 0x00000239E316DC40>: Failed to resolve 'api.telegram.org' ([Errno 11001] getaddrinfo failed)

The above exception was the direct cause of the following exception:

Traceback (most recent call last):
  File "D:\Projects\TgBot\pythonProject1\.venv\Lib\site-packages\requests\adapters.py", line 644, in send
    resp = conn.urlopen(
           ^^^^^^^^^^^^^
  File "D:\Projects\TgBot\pythonProject1\.venv\Lib\site-packages\urllib3\connectionpool.py", line 841, in urlopen
    retries = retries.increment(
              ^^^^^^^^^^^^^^^^^^
  File "D:\Projects\TgBot\pythonProject1\.venv\Lib\site-packages\urllib3\util\retry.py", line 519, in increment
    raise MaxRetryError(_pool, url, reason) from reason  # type: ignore[arg-type]
    ^^^^^^^^^^^^^^^^^^^^^^^^^^^^^^^^^^^^^^^^^^^^^^^^^^^
urllib3.exceptions.MaxRetryError: HTTPSConnectionPool(host='api.telegram.org', port=443): Max retries exceeded with url: /bot8417941208:***********************************/getUpdates?offset=34701296&timeout=20 (Caused by NameResolutionError("<urllib3.connection.HTTPSConnection object at 0x00000239E316DC40>: Failed to resolve 'api.telegram.org' ([Errno 11001] getaddrinfo failed)"))

During handling of the above exception, another exception occurred:

Traceback (most recent call last):
  File "D:\Projects\TgBot\pythonProject1\.venv\Lib\site-packages\telebot\__init__.py", line 1110, in infinity_polling
    self.polling(non_stop=True, timeout=timeout, long_polling_timeout=long_polling_timeout,
  File "D:\Projects\TgBot\pythonProject1\.venv\Lib\site-packages\telebot\__init__.py", line 1198, in polling
    self.__threaded_polling(non_stop=non_stop, interval=interval, timeout=timeout, long_polling_timeout=long_polling_timeout,
  File "D:\Projects\TgBot\pythonProject1\.venv\Lib\site-packages\telebot\__init__.py", line 1273, in __threaded_polling
    raise e
  File "D:\Projects\TgBot\pythonProject1\.venv\Lib\site-packages\telebot\__init__.py", line 1234, in __threaded_polling
    polling_thread.raise_exceptions()
  File "D:\Projects\TgBot\pythonProject1\.venv\Lib\site-packages\telebot\util.py", line 115, in raise_exceptions
    raise self.exception_info
  File "D:\Projects\TgBot\pythonProject1\.venv\Lib\site-packages\telebot\util.py", line 97, in run
    task(*args, **kwargs)
  File "D:\Projects\TgBot\pythonProject1\.venv\Lib\site-packages\telebot\__init__.py", line 688, in __retrieve_updates
    updates = self.get_updates(offset=(self.last_update_id + 1),
              ^^^^^^^^^^^^^^^^^^^^^^^^^^^^^^^^^^^^^^^^^^^^^^^^^^
  File "D:\Projects\TgBot\pythonProject1\.venv\Lib\site-packages\telebot\__init__.py", line 660, in get_updates
    json_updates = apihelper.get_updates(
                   ^^^^^^^^^^^^^^^^^^^^^^
  File "D:\Projects\TgBot\pythonProject1\.venv\Lib\site-packages\telebot\apihelper.py", line 339, in get_updates
    return _make_request(token, method_url, params=payload)
           ^^^^^^^^^^^^^^^^^^^^^^^^^^^^^^^^^^^^^^^^^^^^^^^^
  File "D:\Projects\TgBot\pythonProject1\.venv\Lib\site-packages\telebot\apihelper.py", line 162, in _make_request
    result = _get_req_session().request(
             ^^^^^^^^^^^^^^^^^^^^^^^^^^^
  File "D:\Projects\TgBot\pythonProject1\.venv\Lib\site-packages\requests\sessions.py", line 589, in request
    resp = self.send(prep, **send_kwargs)
           ^^^^^^^^^^^^^^^^^^^^^^^^^^^^^^
  File "D:\Projects\TgBot\pythonProject1\.venv\Lib\site-packages\requests\sessions.py", line 703, in send
    r = adapter.send(request, **kwargs)
        ^^^^^^^^^^^^^^^^^^^^^^^^^^^^^^^
  File "D:\Projects\TgBot\pythonProject1\.venv\Lib\site-packages\requests\adapters.py", line 677, in send
    raise ConnectionError(e, request=request)
requests.exceptions.ConnectionError: HTTPSConnectionPool(host='api.telegram.org', port=443): Max retries exceeded with url: /bot8417941208:***********************************/getUpdates?offset=34701296&timeout=20 (Caused by NameResolutionError("<urllib3.connection.HTTPSConnection object at 0x00000239E316DC40>: Failed to resolve 'api.telegram.org' ([Errno 11001] getaddrinfo failed)"))

2025-09-20 13:00:01,060 - TeleBot - ERROR - Infinity polling exception: HTTPSConnectionPool(host='api.telegram.org', port=443): Max retries exceeded with url: /bot8417941208:***********************************/getUpdates?offset=34701296&timeout=20 (Caused by NameResolutionError("<urllib3.connection.HTTPSConnection object at 0x00000239E2C42BA0>: Failed to resolve 'api.telegram.org' ([Errno 11001] getaddrinfo failed)"))
2025-09-20 13:00:01,063 - TeleBot - ERROR - Exception traceback:
Traceback (most recent call last):
  File "D:\Projects\TgBot\pythonProject1\.venv\Lib\site-packages\urllib3\connection.py", line 198, in _new_conn
    sock = connection.create_connection(
           ^^^^^^^^^^^^^^^^^^^^^^^^^^^^^
  File "D:\Projects\TgBot\pythonProject1\.venv\Lib\site-packages\urllib3\util\connection.py", line 60, in create_connection
    for res in socket.getaddrinfo(host, port, family, socket.SOCK_STREAM):
               ^^^^^^^^^^^^^^^^^^^^^^^^^^^^^^^^^^^^^^^^^^^^^^^^^^^^^^^^^^
  File "C:\Users\Ilya\AppData\Local\Programs\Python\Python312\Lib\socket.py", line 963, in getaddrinfo
    for res in _socket.getaddrinfo(host, port, family, type, proto, flags):
               ^^^^^^^^^^^^^^^^^^^^^^^^^^^^^^^^^^^^^^^^^^^^^^^^^^^^^^^^^^^
socket.gaierror: [Errno 11001] getaddrinfo failed

The above exception was the direct cause of the following exception:

Traceback (most recent call last):
  File "D:\Projects\TgBot\pythonProject1\.venv\Lib\site-packages\urllib3\connectionpool.py", line 787, in urlopen
    response = self._make_request(
               ^^^^^^^^^^^^^^^^^^^
  File "D:\Projects\TgBot\pythonProject1\.venv\Lib\site-packages\urllib3\connectionpool.py", line 488, in _make_request
    raise new_e
  File "D:\Projects\TgBot\pythonProject1\.venv\Lib\site-packages\urllib3\connectionpool.py", line 464, in _make_request
    self._validate_conn(conn)
  File "D:\Projects\TgBot\pythonProject1\.venv\Lib\site-packages\urllib3\connectionpool.py", line 1093, in _validate_conn
    conn.connect()
  File "D:\Projects\TgBot\pythonProject1\.venv\Lib\site-packages\urllib3\connection.py", line 753, in connect
    self.sock = sock = self._new_conn()
                       ^^^^^^^^^^^^^^^^
  File "D:\Projects\TgBot\pythonProject1\.venv\Lib\site-packages\urllib3\connection.py", line 205, in _new_conn
    raise NameResolutionError(self.host, self, e) from e
urllib3.exceptions.NameResolutionError: <urllib3.connection.HTTPSConnection object at 0x00000239E2C42BA0>: Failed to resolve 'api.telegram.org' ([Errno 11001] getaddrinfo failed)

The above exception was the direct cause of the following exception:

Traceback (most recent call last):
  File "D:\Projects\TgBot\pythonProject1\.venv\Lib\site-packages\requests\adapters.py", line 644, in send
    resp = conn.urlopen(
           ^^^^^^^^^^^^^
  File "D:\Projects\TgBot\pythonProject1\.venv\Lib\site-packages\urllib3\connectionpool.py", line 841, in urlopen
    retries = retries.increment(
              ^^^^^^^^^^^^^^^^^^
  File "D:\Projects\TgBot\pythonProject1\.venv\Lib\site-packages\urllib3\util\retry.py", line 519, in increment
    raise MaxRetryError(_pool, url, reason) from reason  # type: ignore[arg-type]
    ^^^^^^^^^^^^^^^^^^^^^^^^^^^^^^^^^^^^^^^^^^^^^^^^^^^
urllib3.exceptions.MaxRetryError: HTTPSConnectionPool(host='api.telegram.org', port=443): Max retries exceeded with url: /bot8417941208:***********************************/getUpdates?offset=34701296&timeout=20 (Caused by NameResolutionError("<urllib3.connection.HTTPSConnection object at 0x00000239E2C42BA0>: Failed to resolve 'api.telegram.org' ([Errno 11001] getaddrinfo failed)"))

During handling of the above exception, another exception occurred:

Traceback (most recent call last):
  File "D:\Projects\TgBot\pythonProject1\.venv\Lib\site-packages\telebot\__init__.py", line 1110, in infinity_polling
    self.polling(non_stop=True, timeout=timeout, long_polling_timeout=long_polling_timeout,
  File "D:\Projects\TgBot\pythonProject1\.venv\Lib\site-packages\telebot\__init__.py", line 1198, in polling
    self.__threaded_polling(non_stop=non_stop, interval=interval, timeout=timeout, long_polling_timeout=long_polling_timeout,
  File "D:\Projects\TgBot\pythonProject1\.venv\Lib\site-packages\telebot\__init__.py", line 1273, in __threaded_polling
    raise e
  File "D:\Projects\TgBot\pythonProject1\.venv\Lib\site-packages\telebot\__init__.py", line 1234, in __threaded_polling
    polling_thread.raise_exceptions()
  File "D:\Projects\TgBot\pythonProject1\.venv\Lib\site-packages\telebot\util.py", line 115, in raise_exceptions
    raise self.exception_info
  File "D:\Projects\TgBot\pythonProject1\.venv\Lib\site-packages\telebot\util.py", line 97, in run
    task(*args, **kwargs)
  File "D:\Projects\TgBot\pythonProject1\.venv\Lib\site-packages\telebot\__init__.py", line 688, in __retrieve_updates
    updates = self.get_updates(offset=(self.last_update_id + 1),
              ^^^^^^^^^^^^^^^^^^^^^^^^^^^^^^^^^^^^^^^^^^^^^^^^^^
  File "D:\Projects\TgBot\pythonProject1\.venv\Lib\site-packages\telebot\__init__.py", line 660, in get_updates
    json_updates = apihelper.get_updates(
                   ^^^^^^^^^^^^^^^^^^^^^^
  File "D:\Projects\TgBot\pythonProject1\.venv\Lib\site-packages\telebot\apihelper.py", line 339, in get_updates
    return _make_request(token, method_url, params=payload)
           ^^^^^^^^^^^^^^^^^^^^^^^^^^^^^^^^^^^^^^^^^^^^^^^^
  File "D:\Projects\TgBot\pythonProject1\.venv\Lib\site-packages\telebot\apihelper.py", line 162, in _make_request
    result = _get_req_session().request(
             ^^^^^^^^^^^^^^^^^^^^^^^^^^^
  File "D:\Projects\TgBot\pythonProject1\.venv\Lib\site-packages\requests\sessions.py", line 589, in request
    resp = self.send(prep, **send_kwargs)
           ^^^^^^^^^^^^^^^^^^^^^^^^^^^^^^
  File "D:\Projects\TgBot\pythonProject1\.venv\Lib\site-packages\requests\sessions.py", line 703, in send
    r = adapter.send(request, **kwargs)
        ^^^^^^^^^^^^^^^^^^^^^^^^^^^^^^^
  File "D:\Projects\TgBot\pythonProject1\.venv\Lib\site-packages\requests\adapters.py", line 677, in send
    raise ConnectionError(e, request=request)
requests.exceptions.ConnectionError: HTTPSConnectionPool(host='api.telegram.org', port=443): Max retries exceeded with url: /bot8417941208:***********************************/getUpdates?offset=34701296&timeout=20 (Caused by NameResolutionError("<urllib3.connection.HTTPSConnection object at 0x00000239E2C42BA0>: Failed to resolve 'api.telegram.org' ([Errno 11001] getaddrinfo failed)"))

2025-09-20 13:00:04,071 - TeleBot - ERROR - Infinity polling exception: HTTPSConnectionPool(host='api.telegram.org', port=443): Max retries exceeded with url: /bot8417941208:***********************************/getUpdates?offset=34701296&timeout=20 (Caused by NameResolutionError("<urllib3.connection.HTTPSConnection object at 0x00000239E316CB60>: Failed to resolve 'api.telegram.org' ([Errno 11001] getaddrinfo failed)"))
2025-09-20 13:00:04,074 - TeleBot - ERROR - Exception traceback:
Traceback (most recent call last):
  File "D:\Projects\TgBot\pythonProject1\.venv\Lib\site-packages\urllib3\connection.py", line 198, in _new_conn
    sock = connection.create_connection(
           ^^^^^^^^^^^^^^^^^^^^^^^^^^^^^
  File "D:\Projects\TgBot\pythonProject1\.venv\Lib\site-packages\urllib3\util\connection.py", line 60, in create_connection
    for res in socket.getaddrinfo(host, port, family, socket.SOCK_STREAM):
               ^^^^^^^^^^^^^^^^^^^^^^^^^^^^^^^^^^^^^^^^^^^^^^^^^^^^^^^^^^
  File "C:\Users\Ilya\AppData\Local\Programs\Python\Python312\Lib\socket.py", line 963, in getaddrinfo
    for res in _socket.getaddrinfo(host, port, family, type, proto, flags):
               ^^^^^^^^^^^^^^^^^^^^^^^^^^^^^^^^^^^^^^^^^^^^^^^^^^^^^^^^^^^
socket.gaierror: [Errno 11001] getaddrinfo failed

The above exception was the direct cause of the following exception:

Traceback (most recent call last):
  File "D:\Projects\TgBot\pythonProject1\.venv\Lib\site-packages\urllib3\connectionpool.py", line 787, in urlopen
    response = self._make_request(
               ^^^^^^^^^^^^^^^^^^^
  File "D:\Projects\TgBot\pythonProject1\.venv\Lib\site-packages\urllib3\connectionpool.py", line 488, in _make_request
    raise new_e
  File "D:\Projects\TgBot\pythonProject1\.venv\Lib\site-packages\urllib3\connectionpool.py", line 464, in _make_request
    self._validate_conn(conn)
  File "D:\Projects\TgBot\pythonProject1\.venv\Lib\site-packages\urllib3\connectionpool.py", line 1093, in _validate_conn
    conn.connect()
  File "D:\Projects\TgBot\pythonProject1\.venv\Lib\site-packages\urllib3\connection.py", line 753, in connect
    self.sock = sock = self._new_conn()
                       ^^^^^^^^^^^^^^^^
  File "D:\Projects\TgBot\pythonProject1\.venv\Lib\site-packages\urllib3\connection.py", line 205, in _new_conn
    raise NameResolutionError(self.host, self, e) from e
urllib3.exceptions.NameResolutionError: <urllib3.connection.HTTPSConnection object at 0x00000239E316CB60>: Failed to resolve 'api.telegram.org' ([Errno 11001] getaddrinfo failed)

The above exception was the direct cause of the following exception:

Traceback (most recent call last):
  File "D:\Projects\TgBot\pythonProject1\.venv\Lib\site-packages\requests\adapters.py", line 644, in send
    resp = conn.urlopen(
           ^^^^^^^^^^^^^
  File "D:\Projects\TgBot\pythonProject1\.venv\Lib\site-packages\urllib3\connectionpool.py", line 841, in urlopen
    retries = retries.increment(
              ^^^^^^^^^^^^^^^^^^
  File "D:\Projects\TgBot\pythonProject1\.venv\Lib\site-packages\urllib3\util\retry.py", line 519, in increment
    raise MaxRetryError(_pool, url, reason) from reason  # type: ignore[arg-type]
    ^^^^^^^^^^^^^^^^^^^^^^^^^^^^^^^^^^^^^^^^^^^^^^^^^^^
urllib3.exceptions.MaxRetryError: HTTPSConnectionPool(host='api.telegram.org', port=443): Max retries exceeded with url: /bot8417941208:***********************************/getUpdates?offset=34701296&timeout=20 (Caused by NameResolutionError("<urllib3.connection.HTTPSConnection object at 0x00000239E316CB60>: Failed to resolve 'api.telegram.org' ([Errno 11001] getaddrinfo failed)"))

During handling of the above exception, another exception occurred:

Traceback (most recent call last):
  File "D:\Projects\TgBot\pythonProject1\.venv\Lib\site-packages\telebot\__init__.py", line 1110, in infinity_polling
    self.polling(non_stop=True, timeout=timeout, long_polling_timeout=long_polling_timeout,
  File "D:\Projects\TgBot\pythonProject1\.venv\Lib\site-packages\telebot\__init__.py", line 1198, in polling
    self.__threaded_polling(non_stop=non_stop, interval=interval, timeout=timeout, long_polling_timeout=long_polling_timeout,
  File "D:\Projects\TgBot\pythonProject1\.venv\Lib\site-packages\telebot\__init__.py", line 1273, in __threaded_polling
    raise e
  File "D:\Projects\TgBot\pythonProject1\.venv\Lib\site-packages\telebot\__init__.py", line 1234, in __threaded_polling
    polling_thread.raise_exceptions()
  File "D:\Projects\TgBot\pythonProject1\.venv\Lib\site-packages\telebot\util.py", line 115, in raise_exceptions
    raise self.exception_info
  File "D:\Projects\TgBot\pythonProject1\.venv\Lib\site-packages\telebot\util.py", line 97, in run
    task(*args, **kwargs)
  File "D:\Projects\TgBot\pythonProject1\.venv\Lib\site-packages\telebot\__init__.py", line 688, in __retrieve_updates
    updates = self.get_updates(offset=(self.last_update_id + 1),
              ^^^^^^^^^^^^^^^^^^^^^^^^^^^^^^^^^^^^^^^^^^^^^^^^^^
  File "D:\Projects\TgBot\pythonProject1\.venv\Lib\site-packages\telebot\__init__.py", line 660, in get_updates
    json_updates = apihelper.get_updates(
                   ^^^^^^^^^^^^^^^^^^^^^^
  File "D:\Projects\TgBot\pythonProject1\.venv\Lib\site-packages\telebot\apihelper.py", line 339, in get_updates
    return _make_request(token, method_url, params=payload)
           ^^^^^^^^^^^^^^^^^^^^^^^^^^^^^^^^^^^^^^^^^^^^^^^^
  File "D:\Projects\TgBot\pythonProject1\.venv\Lib\site-packages\telebot\apihelper.py", line 162, in _make_request
    result = _get_req_session().request(
             ^^^^^^^^^^^^^^^^^^^^^^^^^^^
  File "D:\Projects\TgBot\pythonProject1\.venv\Lib\site-packages\requests\sessions.py", line 589, in request
    resp = self.send(prep, **send_kwargs)
           ^^^^^^^^^^^^^^^^^^^^^^^^^^^^^^
  File "D:\Projects\TgBot\pythonProject1\.venv\Lib\site-packages\requests\sessions.py", line 703, in send
    r = adapter.send(request, **kwargs)
        ^^^^^^^^^^^^^^^^^^^^^^^^^^^^^^^
  File "D:\Projects\TgBot\pythonProject1\.venv\Lib\site-packages\requests\adapters.py", line 677, in send
    raise ConnectionError(e, request=request)
requests.exceptions.ConnectionError: HTTPSConnectionPool(host='api.telegram.org', port=443): Max retries exceeded with url: /bot8417941208:***********************************/getUpdates?offset=34701296&timeout=20 (Caused by NameResolutionError("<urllib3.connection.HTTPSConnection object at 0x00000239E316CB60>: Failed to resolve 'api.telegram.org' ([Errno 11001] getaddrinfo failed)"))

